I'm sorry, but an uncaught exception occurred.

While running game code:
  File "game/script.rpy", line 554, in script call
    call gameloop
  File "game/gameloop.rpy", line 9, in script call
    call maploop
  File "game/script.rpy", line 584, in script call
    call woods
  File "game/script.rpy", line 891, in script call
    call thelovers
  File "game/events/thelovers.rpy", line 114, in script
    $ self.food += 12
  File "game/events/thelovers.rpy", line 114, in <module>
    $ self.food += 12
NameError: name 'self' is not defined

-- Full Traceback ------------------------------------------------------------

Full traceback:
  File "game/script.rpy", line 554, in script call
    call gameloop
  File "game/gameloop.rpy", line 9, in script call
    call maploop
  File "game/script.rpy", line 584, in script call
    call woods
  File "game/script.rpy", line 891, in script call
    call thelovers
  File "game/events/thelovers.rpy", line 114, in script
    $ self.food += 12
  File "/Applications/renpy-7.3.5-sdk/renpy/ast.py", line 914, in execute
    renpy.python.py_exec_bytecode(self.code.bytecode, self.hide, store=self.store)
  File "/Applications/renpy-7.3.5-sdk/renpy/python.py", line 2028, in py_exec_bytecode
    exec bytecode in globals, locals
  File "game/events/thelovers.rpy", line 114, in <module>
    $ self.food += 12
NameError: name 'self' is not defined

Darwin-19.6.0-x86_64-i386-64bit
Ren'Py 7.3.5.606
sunsunsun 1.0
Wed Jul 14 17:33:27 2021
